2020-12-04 01:15:17,066 django.utils.autoreload INFO     Watching for file changes with StatReloader
2020-12-04 01:15:20,114 shapely.geos DEBUG    Trying `CDLL(D:\Django\some\env\lib\site-packages\shapely\DLLs\geos_c.dll)`
2020-12-04 01:15:20,118 shapely.geos DEBUG    Library path: 'D:\\Django\\some\\env\\lib\\site-packages\\shapely\\DLLs\\geos_c.dll'
2020-12-04 01:15:20,118 shapely.geos DEBUG    DLL: <CDLL 'D:\Django\some\env\lib\site-packages\shapely\DLLs\geos_c.dll', handle 7ffd41840000 at 0x151b72005c8>
2020-12-04 01:15:37,832 mainpage.views DEBUG    file: The-Wall-Street-Journal-2.jpg 258532kb
2020-12-04 01:15:37,853 mainpage.views DEBUG    image: JPEG (1480, 804)
2020-12-04 01:15:40,728 mainpage.views ERROR    {(212, 172, 187): '', (101, 110, 22): '', (100, 60, 48): 'STREET', (214, 77, 245): 'L2L', (125, 248, 26): 'JOURNAT'}
2020-12-04 01:15:51,142 asyncio      DEBUG    Using selector: SelectSelector
2020-12-04 01:15:51,505 asyncio      DEBUG    Using selector: SelectSelector
2020-12-04 01:19:09,790 django.utils.autoreload INFO     Watching for file changes with StatReloader
2020-12-04 01:19:13,025 shapely.geos DEBUG    Trying `CDLL(D:\Django\some\env\lib\site-packages\shapely\DLLs\geos_c.dll)`
2020-12-04 01:19:13,148 shapely.geos DEBUG    Library path: 'D:\\Django\\some\\env\\lib\\site-packages\\shapely\\DLLs\\geos_c.dll'
2020-12-04 01:19:13,152 shapely.geos DEBUG    DLL: <CDLL 'D:\Django\some\env\lib\site-packages\shapely\DLLs\geos_c.dll', handle 7ffd3f7e0000 at 0x1bcecb19488>
2020-12-04 01:19:18,020 mainpage.views DEBUG    file: The-Wall-Street-Journal-2.jpg 258532kb
2020-12-04 01:19:18,042 mainpage.views DEBUG    image: JPEG (1480, 804)
2020-12-04 01:19:20,591 mainpage.views ERROR    {(229, 95, 195): '', (135, 243, 11): '', (167, 211, 59): 'STREET', (155, 181, 186): 'L2L', (143, 164, 77): 'JOURNAT'}
2020-12-04 01:19:30,237 asyncio      DEBUG    Using selector: SelectSelector
2020-12-04 01:19:30,628 asyncio      DEBUG    Using selector: SelectSelector
2020-12-04 01:19:42,467 django.utils.autoreload INFO     Watching for file changes with StatReloader
2020-12-04 01:19:45,569 shapely.geos DEBUG    Trying `CDLL(D:\Django\some\env\lib\site-packages\shapely\DLLs\geos_c.dll)`
2020-12-04 01:19:45,573 shapely.geos DEBUG    Library path: 'D:\\Django\\some\\env\\lib\\site-packages\\shapely\\DLLs\\geos_c.dll'
2020-12-04 01:19:45,573 shapely.geos DEBUG    DLL: <CDLL 'D:\Django\some\env\lib\site-packages\shapely\DLLs\geos_c.dll', handle 7ffd3f7e0000 at 0x144f64a8688>
2020-12-04 01:19:57,926 mainpage.views DEBUG    file: The-Wall-Street-Journal-2.jpg 258532kb
2020-12-04 01:19:57,951 mainpage.views DEBUG    image: JPEG (1480, 804)
2020-12-04 01:20:00,478 mainpage.views ERROR    {(242, 212, 214): '', (35, 80, 18): '', (158, 179, 92): 'STREET', (34, 33, 120): 'L2L', (43, 156, 72): 'JOURNAT'}
2020-12-04 01:20:07,277 asyncio      DEBUG    Using selector: SelectSelector
2020-12-04 01:20:07,652 asyncio      DEBUG    Using selector: SelectSelector
2020-12-04 01:28:20,903 django.utils.autoreload INFO     Watching for file changes with StatReloader
2020-12-04 01:28:23,989 shapely.geos DEBUG    Trying `CDLL(D:\Django\some\env\lib\site-packages\shapely\DLLs\geos_c.dll)`
2020-12-04 01:28:23,993 shapely.geos DEBUG    Library path: 'D:\\Django\\some\\env\\lib\\site-packages\\shapely\\DLLs\\geos_c.dll'
2020-12-04 01:28:23,993 shapely.geos DEBUG    DLL: <CDLL 'D:\Django\some\env\lib\site-packages\shapely\DLLs\geos_c.dll', handle 7ffd403a0000 at 0x133993872c8>
2020-12-04 01:28:42,350 mainpage.views DEBUG    file: pidor.png 127705kb
2020-12-04 01:28:42,375 PIL.PngImagePlugin DEBUG    STREAM b'IHDR' 16 13
2020-12-04 01:28:42,412 PIL.PngImagePlugin DEBUG    STREAM b'sRGB' 41 1
2020-12-04 01:28:42,412 PIL.PngImagePlugin DEBUG    STREAM b'gAMA' 54 4
2020-12-04 01:28:42,415 PIL.PngImagePlugin DEBUG    STREAM b'pHYs' 70 9
2020-12-04 01:28:42,417 PIL.PngImagePlugin DEBUG    STREAM b'IDAT' 91 65445
2020-12-04 01:28:42,417 mainpage.views DEBUG    image: PNG (1725, 425)
2020-12-04 01:28:44,106 django.request ERROR    Internal Server Error: /
Traceback (most recent call last):
  File "D:\Django\some\env\lib\site-packages\django\core\handlers\exception.py", line 47, in inner
    response = get_response(request)
  File "D:\Django\some\env\lib\site-packages\django\core\handlers\base.py", line 179, in _get_response
    response = wrapped_callback(request, *callback_args, **callback_kwargs)
  File "D:\Django\some\env\src\mainpage\views.py", line 32, in home_view
    result = ocr.recognise_text(data, cls=False)
  File "D:\Django\some\env\src\Model\OCRModel.py", line 26, in recognise_text
    result = self.ocr_model.ocr(img, det=det, rec=rec, cls=cls)
  File "D:\Django\some\env\lib\site-packages\paddleocr\paddleocr.py", line 242, in ocr
    dt_boxes, rec_res = self.__call__(img)
  File "D:\Django\some\env\lib\site-packages\paddleocr\tools\infer\predict_system.py", line 88, in __call__
    dt_boxes, elapse = self.text_detector(img)
  File "D:\Django\some\env\lib\site-packages\paddleocr\tools\infer\predict_det.py", line 147, in __call__
    self.predictor.run([im])
paddle.fluid.core_avx.EnforceNotMet: 

  Compile Traceback (most recent call last):
    File "/opt/_internal/cpython-3.7.0/lib/python3.7/site-packages/paddle/fluid/framework.py", line 2610, in append_op
    attrs=kwargs.get("attrs", None))

    File "/opt/_internal/cpython-3.7.0/lib/python3.7/site-packages/paddle/fluid/layer_helper.py", line 43, in append_op
    return self.main_program.current_block().append_op(*args, **kwargs)

    File "/opt/_internal/cpython-3.7.0/lib/python3.7/site-packages/paddle/fluid/layers/nn.py", line 2936, in conv2d
    "data_format": data_format,

    File "/root/paddlejob/workspace/env_run/ocr/ppocr/modeling/backbones/det_mobilenet_v3_nose.py", line 153, in conv_bn_layer
    bias_attr=False)

    File "/root/paddlejob/workspace/env_run/ocr/ppocr/modeling/backbones/det_mobilenet_v3_nose.py", line 98, in __call__
    name='conv1')

    File "/root/paddlejob/workspace/env_run/ocr/ppocr/modeling/architectures/det_model.py", line 135, in __call__
    conv_feas = self.backbone(image)

    File "/root/paddlejob/workspace/env_run/ocr/tools/program.py", line 211, in build_export
    image, outputs = model(mode='export')

    File "tools/export_model.py", line 51, in main
    config, eval_program, startup_prog)

    File "tools/export_model.py", line 75, in <module>
    main()


--------------------------------------
C++ Traceback (most recent call last):
--------------------------------------
Windows not support stack backtrace yet.

----------------------
Error Message Summary:
----------------------
InvalidArgumentError: The number of input's channels should be equal to filter's channels * groups for Op(Conv). But received: the input's channels is 4, the input's shape is [1, 4, 224, 960]; the filter's channels is 3, the filter's shape is [8, 3, 3, 3]; the groups is 1, the data_format is NCHW. The error may come from wrong data_format setting.
  [Hint: Expected input_channels == filter_dims[1] * groups, but received input_channels:4 != filter_dims[1] * groups:3.] (at D:\2.0.0-beta0\paddle\paddle\fluid\operators\conv_op.cc:94)
  [operator < conv2d > error]
2020-12-04 01:30:38,621 mainpage.views DEBUG    file: pidor.jpg 127705kb
2020-12-04 01:30:38,624 PIL.PngImagePlugin DEBUG    STREAM b'IHDR' 16 13
2020-12-04 01:30:38,625 PIL.PngImagePlugin DEBUG    STREAM b'sRGB' 41 1
2020-12-04 01:30:38,626 PIL.PngImagePlugin DEBUG    STREAM b'gAMA' 54 4
2020-12-04 01:30:38,627 PIL.PngImagePlugin DEBUG    STREAM b'pHYs' 70 9
2020-12-04 01:30:38,628 PIL.PngImagePlugin DEBUG    STREAM b'IDAT' 91 65445
2020-12-04 01:30:38,629 mainpage.views DEBUG    image: PNG (1725, 425)
2020-12-04 01:30:39,804 django.request ERROR    Internal Server Error: /
Traceback (most recent call last):
  File "D:\Django\some\env\lib\site-packages\django\core\handlers\exception.py", line 47, in inner
    response = get_response(request)
  File "D:\Django\some\env\lib\site-packages\django\core\handlers\base.py", line 179, in _get_response
    response = wrapped_callback(request, *callback_args, **callback_kwargs)
  File "D:\Django\some\env\src\mainpage\views.py", line 32, in home_view
    result = ocr.recognise_text(data, cls=False)
  File "D:\Django\some\env\src\Model\OCRModel.py", line 26, in recognise_text
    result = self.ocr_model.ocr(img, det=det, rec=rec, cls=cls)
  File "D:\Django\some\env\lib\site-packages\paddleocr\paddleocr.py", line 242, in ocr
    dt_boxes, rec_res = self.__call__(img)
  File "D:\Django\some\env\lib\site-packages\paddleocr\tools\infer\predict_system.py", line 88, in __call__
    dt_boxes, elapse = self.text_detector(img)
  File "D:\Django\some\env\lib\site-packages\paddleocr\tools\infer\predict_det.py", line 147, in __call__
    self.predictor.run([im])
paddle.fluid.core_avx.EnforceNotMet: 

  Compile Traceback (most recent call last):
    File "/opt/_internal/cpython-3.7.0/lib/python3.7/site-packages/paddle/fluid/framework.py", line 2610, in append_op
    attrs=kwargs.get("attrs", None))

    File "/opt/_internal/cpython-3.7.0/lib/python3.7/site-packages/paddle/fluid/layer_helper.py", line 43, in append_op
    return self.main_program.current_block().append_op(*args, **kwargs)

    File "/opt/_internal/cpython-3.7.0/lib/python3.7/site-packages/paddle/fluid/layers/nn.py", line 2936, in conv2d
    "data_format": data_format,

    File "/root/paddlejob/workspace/env_run/ocr/ppocr/modeling/backbones/det_mobilenet_v3_nose.py", line 153, in conv_bn_layer
    bias_attr=False)

    File "/root/paddlejob/workspace/env_run/ocr/ppocr/modeling/backbones/det_mobilenet_v3_nose.py", line 98, in __call__
    name='conv1')

    File "/root/paddlejob/workspace/env_run/ocr/ppocr/modeling/architectures/det_model.py", line 135, in __call__
    conv_feas = self.backbone(image)

    File "/root/paddlejob/workspace/env_run/ocr/tools/program.py", line 211, in build_export
    image, outputs = model(mode='export')

    File "tools/export_model.py", line 51, in main
    config, eval_program, startup_prog)

    File "tools/export_model.py", line 75, in <module>
    main()


--------------------------------------
C++ Traceback (most recent call last):
--------------------------------------
Windows not support stack backtrace yet.

----------------------
Error Message Summary:
----------------------
InvalidArgumentError: The number of input's channels should be equal to filter's channels * groups for Op(Conv). But received: the input's channels is 4, the input's shape is [1, 4, 224, 960]; the filter's channels is 3, the filter's shape is [8, 3, 3, 3]; the groups is 1, the data_format is NCHW. The error may come from wrong data_format setting.
  [Hint: Expected input_channels == filter_dims[1] * groups, but received input_channels:4 != filter_dims[1] * groups:3.] (at D:\2.0.0-beta0\paddle\paddle\fluid\operators\conv_op.cc:94)
  [operator < conv2d > error]
2020-12-04 01:30:41,468 asyncio      DEBUG    Using selector: SelectSelector
2020-12-04 01:30:41,810 asyncio      DEBUG    Using selector: SelectSelector
2020-12-04 01:30:48,278 django.utils.autoreload INFO     Watching for file changes with StatReloader
2020-12-04 01:30:52,370 shapely.geos DEBUG    Trying `CDLL(D:\Django\some\env\lib\site-packages\shapely\DLLs\geos_c.dll)`
2020-12-04 01:30:52,374 shapely.geos DEBUG    Library path: 'D:\\Django\\some\\env\\lib\\site-packages\\shapely\\DLLs\\geos_c.dll'
2020-12-04 01:30:52,374 shapely.geos DEBUG    DLL: <CDLL 'D:\Django\some\env\lib\site-packages\shapely\DLLs\geos_c.dll', handle 7ffd40610000 at 0x29cbdb48488>
2020-12-04 01:30:59,035 mainpage.views DEBUG    file: ocr.png 36373kb
2020-12-04 01:30:59,056 mainpage.views DEBUG    image: JPEG (620, 620)
2020-12-04 01:31:27,154 mainpage.views DEBUG    file: pidor.jpg 127705kb
2020-12-04 01:31:27,154 PIL.PngImagePlugin DEBUG    STREAM b'IHDR' 16 13
2020-12-04 01:31:27,156 PIL.PngImagePlugin DEBUG    STREAM b'sRGB' 41 1
2020-12-04 01:31:27,157 PIL.PngImagePlugin DEBUG    STREAM b'gAMA' 54 4
2020-12-04 01:31:27,159 PIL.PngImagePlugin DEBUG    STREAM b'pHYs' 70 9
2020-12-04 01:31:27,160 PIL.PngImagePlugin DEBUG    STREAM b'IDAT' 91 65445
2020-12-04 01:31:27,161 mainpage.views DEBUG    image: PNG (1725, 425)
2020-12-04 01:31:28,437 django.request ERROR    Internal Server Error: /
Traceback (most recent call last):
  File "D:\Django\some\env\lib\site-packages\django\core\handlers\exception.py", line 47, in inner
    response = get_response(request)
  File "D:\Django\some\env\lib\site-packages\django\core\handlers\base.py", line 179, in _get_response
    response = wrapped_callback(request, *callback_args, **callback_kwargs)
  File "D:\Django\some\env\src\mainpage\views.py", line 32, in home_view
    result = ocr.recognise_text(data, cls=False)
  File "D:\Django\some\env\src\Model\OCRModel.py", line 26, in recognise_text
    result = self.ocr_model.ocr(img, det=det, rec=rec, cls=cls)
  File "D:\Django\some\env\lib\site-packages\paddleocr\paddleocr.py", line 242, in ocr
    dt_boxes, rec_res = self.__call__(img)
  File "D:\Django\some\env\lib\site-packages\paddleocr\tools\infer\predict_system.py", line 88, in __call__
    dt_boxes, elapse = self.text_detector(img)
  File "D:\Django\some\env\lib\site-packages\paddleocr\tools\infer\predict_det.py", line 147, in __call__
    self.predictor.run([im])
paddle.fluid.core_avx.EnforceNotMet: 

  Compile Traceback (most recent call last):
    File "/opt/_internal/cpython-3.7.0/lib/python3.7/site-packages/paddle/fluid/framework.py", line 2610, in append_op
    attrs=kwargs.get("attrs", None))

    File "/opt/_internal/cpython-3.7.0/lib/python3.7/site-packages/paddle/fluid/layer_helper.py", line 43, in append_op
    return self.main_program.current_block().append_op(*args, **kwargs)

    File "/opt/_internal/cpython-3.7.0/lib/python3.7/site-packages/paddle/fluid/layers/nn.py", line 2936, in conv2d
    "data_format": data_format,

    File "/root/paddlejob/workspace/env_run/ocr/ppocr/modeling/backbones/det_mobilenet_v3_nose.py", line 153, in conv_bn_layer
    bias_attr=False)

    File "/root/paddlejob/workspace/env_run/ocr/ppocr/modeling/backbones/det_mobilenet_v3_nose.py", line 98, in __call__
    name='conv1')

    File "/root/paddlejob/workspace/env_run/ocr/ppocr/modeling/architectures/det_model.py", line 135, in __call__
    conv_feas = self.backbone(image)

    File "/root/paddlejob/workspace/env_run/ocr/tools/program.py", line 211, in build_export
    image, outputs = model(mode='export')

    File "tools/export_model.py", line 51, in main
    config, eval_program, startup_prog)

    File "tools/export_model.py", line 75, in <module>
    main()


--------------------------------------
C++ Traceback (most recent call last):
--------------------------------------
Windows not support stack backtrace yet.

----------------------
Error Message Summary:
----------------------
InvalidArgumentError: The number of input's channels should be equal to filter's channels * groups for Op(Conv). But received: the input's channels is 4, the input's shape is [1, 4, 224, 960]; the filter's channels is 3, the filter's shape is [8, 3, 3, 3]; the groups is 1, the data_format is NCHW. The error may come from wrong data_format setting.
  [Hint: Expected input_channels == filter_dims[1] * groups, but received input_channels:4 != filter_dims[1] * groups:3.] (at D:\2.0.0-beta0\paddle\paddle\fluid\operators\conv_op.cc:94)
  [operator < conv2d > error]
2020-12-04 01:32:17,807 django.utils.autoreload INFO     D:\Django\some\env\src\mainpage\views.py changed, reloading.
2020-12-04 01:32:17,812 asyncio      DEBUG    Using selector: SelectSelector
2020-12-04 01:32:19,712 django.utils.autoreload INFO     Watching for file changes with StatReloader
2020-12-04 01:32:23,213 shapely.geos DEBUG    Trying `CDLL(D:\Django\some\env\lib\site-packages\shapely\DLLs\geos_c.dll)`
2020-12-04 01:32:23,217 shapely.geos DEBUG    Library path: 'D:\\Django\\some\\env\\lib\\site-packages\\shapely\\DLLs\\geos_c.dll'
2020-12-04 01:32:23,217 shapely.geos DEBUG    DLL: <CDLL 'D:\Django\some\env\lib\site-packages\shapely\DLLs\geos_c.dll', handle 7ffd40610000 at 0x1fa7bee94c8>
2020-12-04 01:32:26,741 mainpage.views DEBUG    file: pidor.jpg 127705kb
2020-12-04 01:32:26,767 PIL.PngImagePlugin DEBUG    STREAM b'IHDR' 16 13
2020-12-04 01:32:26,768 PIL.PngImagePlugin DEBUG    STREAM b'sRGB' 41 1
2020-12-04 01:32:26,770 PIL.PngImagePlugin DEBUG    STREAM b'gAMA' 54 4
2020-12-04 01:32:26,772 PIL.PngImagePlugin DEBUG    STREAM b'pHYs' 70 9
2020-12-04 01:32:26,773 PIL.PngImagePlugin DEBUG    STREAM b'IDAT' 91 65445
2020-12-04 01:32:26,774 mainpage.views DEBUG    image: PNG (1725, 425)
2020-12-04 01:32:26,799 mainpage.views DEBUG    (425, 1725, 4)
2020-12-04 01:32:27,972 django.request ERROR    Internal Server Error: /
Traceback (most recent call last):
  File "D:\Django\some\env\lib\site-packages\django\core\handlers\exception.py", line 47, in inner
    response = get_response(request)
  File "D:\Django\some\env\lib\site-packages\django\core\handlers\base.py", line 179, in _get_response
    response = wrapped_callback(request, *callback_args, **callback_kwargs)
  File "D:\Django\some\env\src\mainpage\views.py", line 32, in home_view
    result = ocr.recognise_text(data, cls=False)
  File "D:\Django\some\env\src\Model\OCRModel.py", line 26, in recognise_text
    result = self.ocr_model.ocr(img, det=det, rec=rec, cls=cls)
  File "D:\Django\some\env\lib\site-packages\paddleocr\paddleocr.py", line 242, in ocr
    dt_boxes, rec_res = self.__call__(img)
  File "D:\Django\some\env\lib\site-packages\paddleocr\tools\infer\predict_system.py", line 88, in __call__
    dt_boxes, elapse = self.text_detector(img)
  File "D:\Django\some\env\lib\site-packages\paddleocr\tools\infer\predict_det.py", line 147, in __call__
    self.predictor.run([im])
paddle.fluid.core_avx.EnforceNotMet: 

  Compile Traceback (most recent call last):
    File "/opt/_internal/cpython-3.7.0/lib/python3.7/site-packages/paddle/fluid/framework.py", line 2610, in append_op
    attrs=kwargs.get("attrs", None))

    File "/opt/_internal/cpython-3.7.0/lib/python3.7/site-packages/paddle/fluid/layer_helper.py", line 43, in append_op
    return self.main_program.current_block().append_op(*args, **kwargs)

    File "/opt/_internal/cpython-3.7.0/lib/python3.7/site-packages/paddle/fluid/layers/nn.py", line 2936, in conv2d
    "data_format": data_format,

    File "/root/paddlejob/workspace/env_run/ocr/ppocr/modeling/backbones/det_mobilenet_v3_nose.py", line 153, in conv_bn_layer
    bias_attr=False)

    File "/root/paddlejob/workspace/env_run/ocr/ppocr/modeling/backbones/det_mobilenet_v3_nose.py", line 98, in __call__
    name='conv1')

    File "/root/paddlejob/workspace/env_run/ocr/ppocr/modeling/architectures/det_model.py", line 135, in __call__
    conv_feas = self.backbone(image)

    File "/root/paddlejob/workspace/env_run/ocr/tools/program.py", line 211, in build_export
    image, outputs = model(mode='export')

    File "tools/export_model.py", line 51, in main
    config, eval_program, startup_prog)

    File "tools/export_model.py", line 75, in <module>
    main()


--------------------------------------
C++ Traceback (most recent call last):
--------------------------------------
Windows not support stack backtrace yet.

----------------------
Error Message Summary:
----------------------
InvalidArgumentError: The number of input's channels should be equal to filter's channels * groups for Op(Conv). But received: the input's channels is 4, the input's shape is [1, 4, 224, 960]; the filter's channels is 3, the filter's shape is [8, 3, 3, 3]; the groups is 1, the data_format is NCHW. The error may come from wrong data_format setting.
  [Hint: Expected input_channels == filter_dims[1] * groups, but received input_channels:4 != filter_dims[1] * groups:3.] (at D:\2.0.0-beta0\paddle\paddle\fluid\operators\conv_op.cc:94)
  [operator < conv2d > error]
2020-12-05 18:48:09,317 django.utils.autoreload INFO     Watching for file changes with StatReloader
2020-12-05 18:48:34,664 asyncio      DEBUG    Using selector: SelectSelector
2020-12-05 18:48:34,938 asyncio      DEBUG    Using selector: SelectSelector
2020-12-05 18:48:45,065 django.utils.autoreload INFO     Watching for file changes with StatReloader
2020-12-05 18:49:07,338 shapely.geos DEBUG    Trying `CDLL(D:\Django\some\env\lib\site-packages\shapely\DLLs\geos_c.dll)`
2020-12-05 18:49:07,715 shapely.geos DEBUG    Library path: 'D:\\Django\\some\\env\\lib\\site-packages\\shapely\\DLLs\\geos_c.dll'
2020-12-05 18:49:07,716 shapely.geos DEBUG    DLL: <CDLL 'D:\Django\some\env\lib\site-packages\shapely\DLLs\geos_c.dll', handle 7ffd413a0000 at 0x278fea39448>
2020-12-05 18:49:20,204 mainpage.views DEBUG    file: 3.jpg 52404kb
2020-12-05 18:49:20,332 mainpage.views DEBUG    image: JPEG (1280, 622)
2020-12-05 18:49:20,520 mainpage.views DEBUG    (622, 1280, 3)
2020-12-05 18:50:43,686 mainpage.views DEBUG    file: 3.jpg 52404kb
2020-12-05 18:50:43,687 mainpage.views DEBUG    image: JPEG (1280, 622)
2020-12-05 18:50:43,716 mainpage.views DEBUG    (622, 1280, 3)
2020-12-05 18:51:11,554 mainpage.views DEBUG    file: The-Wall-Street-Journal-2.jpg 258532kb
2020-12-05 18:51:11,555 mainpage.views DEBUG    image: JPEG (1480, 804)
2020-12-05 18:51:11,578 mainpage.views DEBUG    (804, 1480, 3)
2020-12-05 18:51:13,681 mainpage.views ERROR    {(228, 147, 211): '', (52, 130, 106): '', (204, 250, 29): 'STREET', (69, 38, 8): 'L2L', (173, 8, 224): 'JOURNAT'}
2020-12-05 18:51:42,204 mainpage.views DEBUG    file: The-Wall-Street-Journal-2.jpg 258532kb
2020-12-05 18:51:42,204 mainpage.views DEBUG    image: JPEG (1480, 804)
2020-12-05 18:51:42,228 mainpage.views DEBUG    (804, 1480, 3)
2020-12-05 18:51:44,287 mainpage.views ERROR    {(228, 110, 175): '', (14, 235, 115): '', (35, 98, 25): 'STREET', (62, 127, 8): 'L2L', (39, 85, 172): 'JOURNAT'}
2020-12-05 19:08:02,236 mainpage.views DEBUG    file: The-Wall-Street-Journal-2.jpg 258532kb
2020-12-05 19:08:02,237 mainpage.views DEBUG    image: JPEG (1480, 804)
2020-12-05 19:08:02,265 mainpage.views DEBUG    (804, 1480, 3)
2020-12-05 19:08:05,083 mainpage.views ERROR    {(75, 168, 187): '', (142, 106, 32): '', (194, 190, 83): 'STREET', (35, 18, 200): 'L2L', (53, 239, 89): 'JOURNAT'}
2020-12-05 19:16:00,262 mainpage.views DEBUG    file: ocr.png 36373kb
2020-12-05 19:16:00,263 mainpage.views DEBUG    image: JPEG (620, 620)
2020-12-05 19:16:00,272 mainpage.views DEBUG    (620, 620, 3)
2020-12-05 19:16:45,963 mainpage.views DEBUG    file: Depositphotos_9024726_original.jpg 297373kb
2020-12-05 19:16:45,967 PIL.TiffImagePlugin DEBUG    tag: Copyright (33432) - type: string (2) Tag Location: 22 - Data Location: 26 - value: b'\xc2\xa9 by Jun Yang\x00'
2020-12-05 19:16:45,968 mainpage.views DEBUG    image: JPEG (1024, 680)
2020-12-05 19:16:45,986 mainpage.views DEBUG    (680, 1024, 3)
2020-12-05 19:19:45,697 mainpage.views DEBUG    file: Depositphotos_9024726_original.jpg 297373kb
2020-12-05 19:19:45,698 PIL.TiffImagePlugin DEBUG    tag: Copyright (33432) - type: string (2) Tag Location: 22 - Data Location: 26 - value: b'\xc2\xa9 by Jun Yang\x00'
2020-12-05 19:19:45,700 mainpage.views DEBUG    image: JPEG (1024, 680)
2020-12-05 19:19:45,718 mainpage.views DEBUG    (680, 1024, 3)
2020-12-05 19:20:16,483 mainpage.views DEBUG    file: Depositphotos_9024726_original.jpg 297373kb
2020-12-05 19:20:16,484 PIL.TiffImagePlugin DEBUG    tag: Copyright (33432) - type: string (2) Tag Location: 22 - Data Location: 26 - value: b'\xc2\xa9 by Jun Yang\x00'
2020-12-05 19:20:16,486 mainpage.views DEBUG    image: JPEG (1024, 680)
2020-12-05 19:20:16,506 mainpage.views DEBUG    (680, 1024, 3)
2020-12-05 19:20:45,270 mainpage.views DEBUG    file: The-Wall-Street-Journal-2.jpg 258532kb
2020-12-05 19:20:45,272 mainpage.views DEBUG    image: JPEG (1480, 804)
2020-12-05 19:20:45,297 mainpage.views DEBUG    (804, 1480, 3)
2020-12-05 19:20:47,398 mainpage.views ERROR    {(26, 125, 213): '', (247, 47, 0): '', (139, 14, 212): 'STREET', (39, 142, 0): 'L2L', (144, 227, 151): 'JOURNAT'}
2020-12-05 19:21:23,697 mainpage.views DEBUG    file: The-Wall-Street-Journal-2.jpg 258532kb
2020-12-05 19:21:23,741 mainpage.views DEBUG    image: JPEG (1480, 804)
2020-12-05 19:21:23,763 mainpage.views DEBUG    (804, 1480, 3)
2020-12-05 19:21:25,846 mainpage.views ERROR    {(127, 69, 204): '', (191, 200, 8): '', (182, 141, 7): 'STREET', (124, 240, 145): 'L2L', (219, 118, 109): 'JOURNAT'}
2020-12-05 19:22:55,084 mainpage.views DEBUG    file: covermid.jpg 31454kb
2020-12-05 19:22:55,086 mainpage.views DEBUG    image: JPEG (500, 376)
2020-12-05 19:22:55,091 mainpage.views DEBUG    (376, 500, 3)
2020-12-05 19:22:56,505 mainpage.views ERROR    {(238, 181, 119): 'SKDA', (193, 78, 216): 'WARDTORS'}
2020-12-05 19:23:41,612 mainpage.views DEBUG    file: 3.jpg 52404kb
2020-12-05 19:23:41,613 mainpage.views DEBUG    image: JPEG (1280, 622)
2020-12-05 19:23:41,634 mainpage.views DEBUG    (622, 1280, 3)
2020-12-05 19:23:42,342 mainpage.views DEBUG    file: 2.jpg 50404kb
2020-12-05 19:23:42,344 mainpage.views DEBUG    image: JPEG (1280, 622)
2020-12-05 19:23:42,659 mainpage.views DEBUG    (622, 1280, 3)
2020-12-05 19:23:42,668 mainpage.views DEBUG    file: 2.jpg 50404kb
2020-12-05 19:23:43,003 mainpage.views DEBUG    image: JPEG (1280, 622)
2020-12-05 19:23:43,391 mainpage.views DEBUG    (622, 1280, 3)
2020-12-05 19:32:35,124 asyncio      DEBUG    Using selector: SelectSelector
2021-01-01 14:01:10,623 django.utils.autoreload INFO     Watching for file changes with StatReloader
2021-01-01 14:02:13,843 shapely.geos DEBUG    Trying `CDLL(D:\Django\some\env\lib\site-packages\shapely\DLLs\geos_c.dll)`
2021-01-01 14:02:14,282 shapely.geos DEBUG    Library path: 'D:\\Django\\some\\env\\lib\\site-packages\\shapely\\DLLs\\geos_c.dll'
2021-01-01 14:02:14,283 shapely.geos DEBUG    DLL: <CDLL 'D:\Django\some\env\lib\site-packages\shapely\DLLs\geos_c.dll', handle 7ffeec070000 at 0x1a514168488>
2021-01-01 14:09:30,185 mainpage.views DEBUG    file: 2.jpg 50404kb
2021-01-01 14:09:30,291 mainpage.views DEBUG    image: JPEG (1280, 622)
2021-01-01 14:09:30,374 mainpage.views DEBUG    (622, 1280, 3)
